WARNING 2019-02-19 11:44:37,571 base 152 Not Found: /users/username/count
WARNING 2019-02-19 11:44:37,575 basehttp 124 "POST /users/username/count HTTP/1.1" 404 2195
WARNING 2019-02-19 11:44:43,841 base 152 Not Found: /users/username/count
WARNING 2019-02-19 11:44:43,846 basehttp 124 "GET /users/username/count HTTP/1.1" 404 2194
WARNING 2019-02-19 11:45:13,060 base 152 Not Found: /users/username/ddd/count
WARNING 2019-02-19 11:45:13,070 basehttp 124 "GET /users/username/ddd/count HTTP/1.1" 404 2206
WARNING 2019-02-19 11:45:26,936 base 152 Not Found: /users/usernames/ddd/count
WARNING 2019-02-19 11:45:26,939 basehttp 124 "GET /users/usernames/ddd/count HTTP/1.1" 404 2209
WARNING 2019-02-19 11:45:33,025 base 152 Not Found: /users/usernames/ddd/count/
WARNING 2019-02-19 11:45:33,029 basehttp 124 "GET /users/usernames/ddd/count/ HTTP/1.1" 404 2212
WARNING 2019-02-19 11:47:00,250 base 152 Not Found: /users/usernames/ddddd/count/
WARNING 2019-02-19 11:47:00,256 basehttp 124 "GET /users/usernames/ddddd/count/ HTTP/1.1" 404 2218
WARNING 2019-02-19 11:47:01,349 base 152 Not Found: /users/usernames/ddddd/count/
WARNING 2019-02-19 11:47:01,356 basehttp 124 "GET /users/usernames/ddddd/count/ HTTP/1.1" 404 2218
WARNING 2019-02-19 11:47:02,497 base 152 Not Found: /users/usernames/ddddd/count/
WARNING 2019-02-19 11:47:02,504 basehttp 124 "GET /users/usernames/ddddd/count/ HTTP/1.1" 404 2218
WARNING 2019-02-19 11:47:27,219 base 152 Not Found: /users/usernames/ddddd/count/
WARNING 2019-02-19 11:47:27,227 basehttp 124 "GET /users/usernames/ddddd/count/ HTTP/1.1" 404 2218
ERROR 2019-02-19 11:48:22,646 exception 135 Internal Server Error: /users/users/usernames/ddddd/count/
Traceback (most recent call last):
  File "/home/python/.virtualenvs/django_meiduo/lib/python3.5/site-packages/django/core/handlers/exception.py", line 41, in inner
    response = get_response(request)
  File "/home/python/.virtualenvs/django_meiduo/lib/python3.5/site-packages/django/core/handlers/base.py", line 187, in _get_response
    response = self.process_exception_by_middleware(e, request)
  File "/home/python/.virtualenvs/django_meiduo/lib/python3.5/site-packages/django/core/handlers/base.py", line 185, in _get_response
    response = wrapped_callback(request, *callback_args, **callback_kwargs)
  File "/home/python/.virtualenvs/django_meiduo/lib/python3.5/site-packages/django/views/decorators/csrf.py", line 58, in wrapped_view
    return view_func(*args, **kwargs)
  File "/home/python/.virtualenvs/django_meiduo/lib/python3.5/site-packages/django/views/generic/base.py", line 68, in view
    return self.dispatch(request, *args, **kwargs)
  File "/home/python/.virtualenvs/django_meiduo/lib/python3.5/site-packages/rest_framework/views.py", line 483, in dispatch
    response = self.handle_exception(exc)
  File "/home/python/.virtualenvs/django_meiduo/lib/python3.5/site-packages/rest_framework/views.py", line 443, in handle_exception
    self.raise_uncaught_exception(exc)
  File "/home/python/.virtualenvs/django_meiduo/lib/python3.5/site-packages/rest_framework/views.py", line 480, in dispatch
    response = handler(request, *args, **kwargs)
  File "/home/python/Desktop/meiduo/meiduo_demo/mall/apps/users/views.py", line 22, in get
    count = User.objects.filters(username=username).count()
AttributeError: 'UserManager' object has no attribute 'filters'
ERROR 2019-02-19 11:48:22,723 basehttp 124 "GET /users/users/usernames/ddddd/count/ HTTP/1.1" 500 16990
ERROR 2019-02-19 11:48:36,620 exception 135 Internal Server Error: /users/usernames/ddddd/count/
Traceback (most recent call last):
  File "/home/python/.virtualenvs/django_meiduo/lib/python3.5/site-packages/django/core/handlers/exception.py", line 41, in inner
    response = get_response(request)
  File "/home/python/.virtualenvs/django_meiduo/lib/python3.5/site-packages/django/core/handlers/base.py", line 187, in _get_response
    response = self.process_exception_by_middleware(e, request)
  File "/home/python/.virtualenvs/django_meiduo/lib/python3.5/site-packages/django/core/handlers/base.py", line 185, in _get_response
    response = wrapped_callback(request, *callback_args, **callback_kwargs)
  File "/home/python/.virtualenvs/django_meiduo/lib/python3.5/site-packages/django/views/decorators/csrf.py", line 58, in wrapped_view
    return view_func(*args, **kwargs)
  File "/home/python/.virtualenvs/django_meiduo/lib/python3.5/site-packages/django/views/generic/base.py", line 68, in view
    return self.dispatch(request, *args, **kwargs)
  File "/home/python/.virtualenvs/django_meiduo/lib/python3.5/site-packages/rest_framework/views.py", line 483, in dispatch
    response = self.handle_exception(exc)
  File "/home/python/.virtualenvs/django_meiduo/lib/python3.5/site-packages/rest_framework/views.py", line 443, in handle_exception
    self.raise_uncaught_exception(exc)
  File "/home/python/.virtualenvs/django_meiduo/lib/python3.5/site-packages/rest_framework/views.py", line 480, in dispatch
    response = handler(request, *args, **kwargs)
  File "/home/python/Desktop/meiduo/meiduo_demo/mall/apps/users/views.py", line 22, in get
    count = User.objects.filters(username=username).count()
AttributeError: 'UserManager' object has no attribute 'filters'
ERROR 2019-02-19 11:48:36,651 basehttp 124 "GET /users/usernames/ddddd/count/ HTTP/1.1" 500 16966
INFO 2019-02-19 11:52:17,878 basehttp 124 "GET /users/usernames/ddddd/count/ HTTP/1.1" 200 11
INFO 2019-02-19 12:07:17,939 basehttp 124 "GET /users/usernames/itcast/count/ HTTP/1.1" 200 11
INFO 2019-02-19 13:09:57,318 basehttp 124 "GET /verifications/imagecodes/12345 HTTP/1.1" 301 0
ERROR 2019-02-19 13:09:57,322 exception 135 Internal Server Error: /verifications/imagecodes/12345/
Traceback (most recent call last):
  File "/home/python/.virtualenvs/django_meiduo/lib/python3.5/site-packages/django/core/handlers/exception.py", line 41, in inner
    response = get_response(request)
  File "/home/python/.virtualenvs/django_meiduo/lib/python3.5/site-packages/django/core/handlers/base.py", line 187, in _get_response
    response = self.process_exception_by_middleware(e, request)
  File "/home/python/.virtualenvs/django_meiduo/lib/python3.5/site-packages/django/core/handlers/base.py", line 185, in _get_response
    response = wrapped_callback(request, *callback_args, **callback_kwargs)
  File "/home/python/.virtualenvs/django_meiduo/lib/python3.5/site-packages/django/views/decorators/csrf.py", line 58, in wrapped_view
    return view_func(*args, **kwargs)
  File "/home/python/.virtualenvs/django_meiduo/lib/python3.5/site-packages/django/views/generic/base.py", line 68, in view
    return self.dispatch(request, *args, **kwargs)
  File "/home/python/.virtualenvs/django_meiduo/lib/python3.5/site-packages/rest_framework/views.py", line 483, in dispatch
    response = self.handle_exception(exc)
  File "/home/python/.virtualenvs/django_meiduo/lib/python3.5/site-packages/rest_framework/views.py", line 443, in handle_exception
    self.raise_uncaught_exception(exc)
  File "/home/python/.virtualenvs/django_meiduo/lib/python3.5/site-packages/rest_framework/views.py", line 480, in dispatch
    response = handler(request, *args, **kwargs)
  File "/home/python/Desktop/meiduo/meiduo_demo/mall/apps/verifications/views.py", line 25, in get
    text,image = captcha.generate_captcha()
AttributeError: module 'libs.captcha.captcha' has no attribute 'generate_captcha'
ERROR 2019-02-19 13:09:57,357 basehttp 124 "GET /verifications/imagecodes/12345/ HTTP/1.1" 500 17269
INFO 2019-02-19 13:13:18,570 basehttp 124 "GET /verifications/imagecodes/12345 HTTP/1.1" 301 0
ERROR 2019-02-19 13:13:18,585 exception 135 Internal Server Error: /verifications/imagecodes/12345/
Traceback (most recent call last):
  File "/home/python/.virtualenvs/django_meiduo/lib/python3.5/site-packages/django/core/handlers/exception.py", line 41, in inner
    response = get_response(request)
  File "/home/python/.virtualenvs/django_meiduo/lib/python3.5/site-packages/django/core/handlers/base.py", line 187, in _get_response
    response = self.process_exception_by_middleware(e, request)
  File "/home/python/.virtualenvs/django_meiduo/lib/python3.5/site-packages/django/core/handlers/base.py", line 185, in _get_response
    response = wrapped_callback(request, *callback_args, **callback_kwargs)
  File "/home/python/.virtualenvs/django_meiduo/lib/python3.5/site-packages/django/views/decorators/csrf.py", line 58, in wrapped_view
    return view_func(*args, **kwargs)
  File "/home/python/.virtualenvs/django_meiduo/lib/python3.5/site-packages/django/views/generic/base.py", line 68, in view
    return self.dispatch(request, *args, **kwargs)
  File "/home/python/.virtualenvs/django_meiduo/lib/python3.5/site-packages/rest_framework/views.py", line 483, in dispatch
    response = self.handle_exception(exc)
  File "/home/python/.virtualenvs/django_meiduo/lib/python3.5/site-packages/rest_framework/views.py", line 443, in handle_exception
    self.raise_uncaught_exception(exc)
  File "/home/python/.virtualenvs/django_meiduo/lib/python3.5/site-packages/rest_framework/views.py", line 480, in dispatch
    response = handler(request, *args, **kwargs)
  File "/home/python/Desktop/meiduo/meiduo_demo/mall/apps/verifications/views.py", line 27, in get
    text,image = Captcha.generate_captcha()
TypeError: generate_captcha() missing 1 required positional argument: 'self'
ERROR 2019-02-19 13:13:18,612 basehttp 124 "GET /verifications/imagecodes/12345/ HTTP/1.1" 500 17259
INFO 2019-02-19 13:13:57,546 basehttp 124 "GET /verifications/imagecodes/12345 HTTP/1.1" 301 0
ERROR 2019-02-19 13:13:57,560 exception 135 Internal Server Error: /verifications/imagecodes/12345/
Traceback (most recent call last):
  File "/home/python/.virtualenvs/django_meiduo/lib/python3.5/site-packages/django/core/handlers/exception.py", line 41, in inner
    response = get_response(request)
  File "/home/python/.virtualenvs/django_meiduo/lib/python3.5/site-packages/django/core/handlers/base.py", line 187, in _get_response
    response = self.process_exception_by_middleware(e, request)
  File "/home/python/.virtualenvs/django_meiduo/lib/python3.5/site-packages/django/core/handlers/base.py", line 185, in _get_response
    response = wrapped_callback(request, *callback_args, **callback_kwargs)
  File "/home/python/.virtualenvs/django_meiduo/lib/python3.5/site-packages/django/views/decorators/csrf.py", line 58, in wrapped_view
    return view_func(*args, **kwargs)
  File "/home/python/.virtualenvs/django_meiduo/lib/python3.5/site-packages/django/views/generic/base.py", line 68, in view
    return self.dispatch(request, *args, **kwargs)
  File "/home/python/.virtualenvs/django_meiduo/lib/python3.5/site-packages/rest_framework/views.py", line 483, in dispatch
    response = self.handle_exception(exc)
  File "/home/python/.virtualenvs/django_meiduo/lib/python3.5/site-packages/rest_framework/views.py", line 443, in handle_exception
    self.raise_uncaught_exception(exc)
  File "/home/python/.virtualenvs/django_meiduo/lib/python3.5/site-packages/rest_framework/views.py", line 480, in dispatch
    response = handler(request, *args, **kwargs)
  File "/home/python/Desktop/meiduo/meiduo_demo/mall/apps/verifications/views.py", line 27, in get
    text,image = Captcha.generate_captcha(image_code_id)
  File "/home/python/Desktop/meiduo/meiduo_demo/mall/apps/libs/captcha/captcha.py", line 214, in generate_captcha
    self.initialize()
AttributeError: 'str' object has no attribute 'initialize'
ERROR 2019-02-19 13:13:57,593 basehttp 124 "GET /verifications/imagecodes/12345/ HTTP/1.1" 500 17371
INFO 2019-02-19 13:16:04,100 basehttp 124 "GET /verifications/imagecodes/12345 HTTP/1.1" 301 0
ERROR 2019-02-19 13:16:04,118 exception 135 Internal Server Error: /verifications/imagecodes/12345/
Traceback (most recent call last):
  File "/home/python/.virtualenvs/django_meiduo/lib/python3.5/site-packages/django/core/handlers/exception.py", line 41, in inner
    response = get_response(request)
  File "/home/python/.virtualenvs/django_meiduo/lib/python3.5/site-packages/django/core/handlers/base.py", line 187, in _get_response
    response = self.process_exception_by_middleware(e, request)
  File "/home/python/.virtualenvs/django_meiduo/lib/python3.5/site-packages/django/core/handlers/base.py", line 185, in _get_response
    response = wrapped_callback(request, *callback_args, **callback_kwargs)
  File "/home/python/.virtualenvs/django_meiduo/lib/python3.5/site-packages/django/views/decorators/csrf.py", line 58, in wrapped_view
    return view_func(*args, **kwargs)
  File "/home/python/.virtualenvs/django_meiduo/lib/python3.5/site-packages/django/views/generic/base.py", line 68, in view
    return self.dispatch(request, *args, **kwargs)
  File "/home/python/.virtualenvs/django_meiduo/lib/python3.5/site-packages/rest_framework/views.py", line 483, in dispatch
    response = self.handle_exception(exc)
  File "/home/python/.virtualenvs/django_meiduo/lib/python3.5/site-packages/rest_framework/views.py", line 443, in handle_exception
    self.raise_uncaught_exception(exc)
  File "/home/python/.virtualenvs/django_meiduo/lib/python3.5/site-packages/rest_framework/views.py", line 480, in dispatch
    response = handler(request, *args, **kwargs)
  File "/home/python/Desktop/meiduo/meiduo_demo/mall/apps/verifications/views.py", line 26, in get
    text,image = captcha.generate_captcha(image_code_id)
TypeError: generate_captcha() takes 1 positional argument but 2 were given
ERROR 2019-02-19 13:16:04,145 basehttp 124 "GET /verifications/imagecodes/12345/ HTTP/1.1" 500 17268
INFO 2019-02-19 13:16:27,027 basehttp 124 "GET /verifications/imagecodes/12345 HTTP/1.1" 301 0
INFO 2019-02-19 13:16:27,064 basehttp 124 "GET /verifications/imagecodes/12345/ HTTP/1.1" 200 3068
<<<<<<< HEAD
INFO 2019-02-19 14:21:46,031 basehttp 124 "GET /verifications/imagecodes/a46ce7bb-bbe6-48e7-8699-556c6e23f493/ HTTP/1.1" 200 3381
INFO 2019-02-19 14:23:19,181 basehttp 124 "GET /verifications/imagecodes/b3467156-5e23-4c8a-8c8a-1ef2b9da907a/ HTTP/1.1" 200 3332
INFO 2019-02-19 14:23:42,626 basehttp 124 "GET /users/usernames/dsfas/count/ HTTP/1.1" 200 11
INFO 2019-02-19 14:23:47,672 basehttp 124 "GET /users/usernames/dsfasd/count/ HTTP/1.1" 200 11
INFO 2019-02-19 14:24:38,975 basehttp 124 "GET /verifications/imagecodes/53cc39cd-2dd1-4c1d-8ccd-84dfd2a28e04/ HTTP/1.1" 200 3480
INFO 2019-02-19 14:24:39,689 basehttp 124 "GET /verifications/imagecodes/a9f36883-0f86-4df5-b3b9-719d846fac71/ HTTP/1.1" 200 3086
INFO 2019-02-19 14:24:40,638 basehttp 124 "GET /verifications/imagecodes/fb1126ac-61b7-4c4b-8edb-45c989cab254/ HTTP/1.1" 200 3484
INFO 2019-02-19 14:24:41,963 basehttp 124 "GET /verifications/imagecodes/fb8798a5-4c19-464f-86f6-5e2452b99a45/ HTTP/1.1" 200 3193
INFO 2019-02-19 14:24:42,542 basehttp 124 "GET /verifications/imagecodes/454b41b6-e60e-4a45-aa78-59a4c0e1bc3b/ HTTP/1.1" 200 3123
INFO 2019-02-19 14:24:43,073 basehttp 124 "GET /verifications/imagecodes/67c1f6e8-ad85-4c20-b269-8b4811e414e0/ HTTP/1.1" 200 3589
INFO 2019-02-19 14:46:25,088 basehttp 124 "GET /verifications/imagecodes/de5aadbf-8a0e-49d0-baaf-65b0f96a41f1/ HTTP/1.1" 200 3013
INFO 2019-02-19 14:46:27,220 basehttp 124 "GET /verifications/imagecodes/5e78732d-2f65-4c44-a3aa-427e642f795f/ HTTP/1.1" 200 3432
INFO 2019-02-19 14:46:28,029 basehttp 124 "GET /verifications/imagecodes/e03df854-be10-4e81-99a5-442880efd5dc/ HTTP/1.1" 200 3520
=======
>>>>>>> 6c434f3d206b553fa9330fae690f47af94fe278e
INFO 2019-02-20 15:42:30,758 basehttp 124 "GET /verifications/imagecodes/12345 HTTP/1.1" 301 0
INFO 2019-02-20 15:42:30,828 basehttp 124 "GET /verifications/imagecodes/12345/ HTTP/1.1" 200 3008
WARNING 2019-02-20 15:42:30,960 base 152 Not Found: /favicon.ico
WARNING 2019-02-20 15:42:30,971 basehttp 124 "GET /favicon.ico HTTP/1.1" 404 2182
INFO 2019-02-20 15:42:34,414 basehttp 124 "GET /verifications/imagecodes/12345/ HTTP/1.1" 200 3614
INFO 2019-02-20 15:45:48,956 basehttp 124 "GET /verifications/imagecodes/34252/ HTTP/1.1" 200 3145
INFO 2019-02-20 15:46:22,511 basehttp 124 "GET /verifications/imagecodes/34251/ HTTP/1.1" 200 3574
INFO 2019-02-20 15:49:16,911 basehttp 124 "GET /verifications/imagecodes/ed7c7030-0c4b-415a-a4b0-a76da679171b/ HTTP/1.1" 200 3248
INFO 2019-02-20 15:49:22,691 basehttp 124 "GET /verifications/imagecodes/5fa24226-605f-4a61-ad7f-c1821e6b8094/ HTTP/1.1" 200 3027
ERROR 2019-02-20 15:51:28,531 exception 135 Internal Server Error: /verifications/smscodes/13111111111/
Traceback (most recent call last):
  File "/home/python/.virtualenvs/django_meiduo/lib/python3.5/site-packages/django/core/handlers/exception.py", line 41, in inner
    response = get_response(request)
  File "/home/python/.virtualenvs/django_meiduo/lib/python3.5/site-packages/django/core/handlers/base.py", line 187, in _get_response
    response = self.process_exception_by_middleware(e, request)
  File "/home/python/.virtualenvs/django_meiduo/lib/python3.5/site-packages/django/core/handlers/base.py", line 185, in _get_response
    response = wrapped_callback(request, *callback_args, **callback_kwargs)
  File "/home/python/.virtualenvs/django_meiduo/lib/python3.5/site-packages/django/views/decorators/csrf.py", line 58, in wrapped_view
    return view_func(*args, **kwargs)
  File "/home/python/.virtualenvs/django_meiduo/lib/python3.5/site-packages/django/views/generic/base.py", line 68, in view
    return self.dispatch(request, *args, **kwargs)
  File "/home/python/.virtualenvs/django_meiduo/lib/python3.5/site-packages/rest_framework/views.py", line 485, in dispatch
    self.response = self.finalize_response(request, response, *args, **kwargs)
  File "/home/python/.virtualenvs/django_meiduo/lib/python3.5/site-packages/rest_framework/views.py", line 400, in finalize_response
    % type(response)
AssertionError: Expected a `Response`, `HttpResponse` or `HttpStreamingResponse` to be returned from the view, but received a `<class 'NoneType'>`
ERROR 2019-02-20 15:51:28,730 basehttp 124 "GET /verifications/smscodes/13111111111/?text=krwt&image_code_id=5fa24226-605f-4a61-ad7f-c1821e6b8094 HTTP/1.1" 500 88812
INFO 2019-02-20 15:52:37,747 basehttp 124 "GET /verifications/imagecodes/ba026cd8-bc35-4129-af1e-2016c7d2f01a/ HTTP/1.1" 200 3622
ERROR 2019-02-20 15:53:23,859 exception 135 Internal Server Error: /verifications/smscodes/13111111111/
Traceback (most recent call last):
  File "/home/python/.virtualenvs/django_meiduo/lib/python3.5/site-packages/django/core/handlers/exception.py", line 41, in inner
    response = get_response(request)
  File "/home/python/.virtualenvs/django_meiduo/lib/python3.5/site-packages/django/core/handlers/base.py", line 187, in _get_response
    response = self.process_exception_by_middleware(e, request)
  File "/home/python/.virtualenvs/django_meiduo/lib/python3.5/site-packages/django/core/handlers/base.py", line 185, in _get_response
    response = wrapped_callback(request, *callback_args, **callback_kwargs)
  File "/home/python/.virtualenvs/django_meiduo/lib/python3.5/site-packages/django/views/decorators/csrf.py", line 58, in wrapped_view
    return view_func(*args, **kwargs)
  File "/home/python/.virtualenvs/django_meiduo/lib/python3.5/site-packages/django/views/generic/base.py", line 68, in view
    return self.dispatch(request, *args, **kwargs)
  File "/home/python/.virtualenvs/django_meiduo/lib/python3.5/site-packages/rest_framework/views.py", line 485, in dispatch
    self.response = self.finalize_response(request, response, *args, **kwargs)
  File "/home/python/.virtualenvs/django_meiduo/lib/python3.5/site-packages/rest_framework/views.py", line 400, in finalize_response
    % type(response)
AssertionError: Expected a `Response`, `HttpResponse` or `HttpStreamingResponse` to be returned from the view, but received a `<class 'NoneType'>`
ERROR 2019-02-20 15:53:24,048 basehttp 124 "GET /verifications/smscodes/13111111111/?text=lnmk&image_code_id=ba026cd8-bc35-4129-af1e-2016c7d2f01a HTTP/1.1" 500 88812
ERROR 2019-02-20 15:54:18,657 exception 135 Internal Server Error: /verifications/smscodes/13111111111/
Traceback (most recent call last):
  File "/home/python/.virtualenvs/django_meiduo/lib/python3.5/site-packages/django/core/handlers/exception.py", line 41, in inner
    response = get_response(request)
  File "/home/python/.virtualenvs/django_meiduo/lib/python3.5/site-packages/django/core/handlers/base.py", line 187, in _get_response
    response = self.process_exception_by_middleware(e, request)
  File "/home/python/.virtualenvs/django_meiduo/lib/python3.5/site-packages/django/core/handlers/base.py", line 185, in _get_response
    response = wrapped_callback(request, *callback_args, **callback_kwargs)
  File "/home/python/.virtualenvs/django_meiduo/lib/python3.5/site-packages/django/views/decorators/csrf.py", line 58, in wrapped_view
    return view_func(*args, **kwargs)
  File "/home/python/.virtualenvs/django_meiduo/lib/python3.5/site-packages/django/views/generic/base.py", line 68, in view
    return self.dispatch(request, *args, **kwargs)
  File "/home/python/.virtualenvs/django_meiduo/lib/python3.5/site-packages/rest_framework/views.py", line 485, in dispatch
    self.response = self.finalize_response(request, response, *args, **kwargs)
  File "/home/python/.virtualenvs/django_meiduo/lib/python3.5/site-packages/rest_framework/views.py", line 400, in finalize_response
    % type(response)
AssertionError: Expected a `Response`, `HttpResponse` or `HttpStreamingResponse` to be returned from the view, but received a `<class 'NoneType'>`
ERROR 2019-02-20 15:54:18,856 basehttp 124 "GET /verifications/smscodes/13111111111/?text=lnmk&image_code_id=ba026cd8-bc35-4129-af1e-2016c7d2f01a HTTP/1.1" 500 88812
INFO 2019-02-20 16:00:02,894 basehttp 124 "GET /verifications/imagecodes/7decab95-22b5-4887-9a79-b16120cfc680/ HTTP/1.1" 200 3314
ERROR 2019-02-20 16:01:01,211 exception 135 Internal Server Error: /verifications/smscodes/13111111111/
Traceback (most recent call last):
  File "/home/python/.virtualenvs/django_meiduo/lib/python3.5/site-packages/django/core/handlers/exception.py", line 41, in inner
    response = get_response(request)
  File "/home/python/.virtualenvs/django_meiduo/lib/python3.5/site-packages/django/core/handlers/base.py", line 187, in _get_response
    response = self.process_exception_by_middleware(e, request)
  File "/home/python/.virtualenvs/django_meiduo/lib/python3.5/site-packages/django/core/handlers/base.py", line 185, in _get_response
    response = wrapped_callback(request, *callback_args, **callback_kwargs)
  File "/home/python/.virtualenvs/django_meiduo/lib/python3.5/site-packages/django/views/decorators/csrf.py", line 58, in wrapped_view
    return view_func(*args, **kwargs)
  File "/home/python/.virtualenvs/django_meiduo/lib/python3.5/site-packages/django/views/generic/base.py", line 68, in view
    return self.dispatch(request, *args, **kwargs)
  File "/home/python/.virtualenvs/django_meiduo/lib/python3.5/site-packages/rest_framework/views.py", line 485, in dispatch
    self.response = self.finalize_response(request, response, *args, **kwargs)
  File "/home/python/.virtualenvs/django_meiduo/lib/python3.5/site-packages/rest_framework/views.py", line 400, in finalize_response
    % type(response)
AssertionError: Expected a `Response`, `HttpResponse` or `HttpStreamingResponse` to be returned from the view, but received a `<class 'NoneType'>`
ERROR 2019-02-20 16:01:01,410 basehttp 124 "GET /verifications/smscodes/13111111111/?text=k6ih&image_code_id=7decab95-22b5-4887-9a79-b16120cfc680 HTTP/1.1" 500 88812
INFO 2019-02-20 16:03:45,816 basehttp 124 "GET /verifications/imagecodes/2b196af9-c6bf-4823-94fa-872bdae408ff/ HTTP/1.1" 200 2892
ERROR 2019-02-20 16:04:24,751 exception 135 Internal Server Error: /verifications/smscodes/13111111111/
Traceback (most recent call last):
  File "/home/python/.virtualenvs/django_meiduo/lib/python3.5/site-packages/django/core/handlers/exception.py", line 41, in inner
    response = get_response(request)
  File "/home/python/.virtualenvs/django_meiduo/lib/python3.5/site-packages/django/core/handlers/base.py", line 187, in _get_response
    response = self.process_exception_by_middleware(e, request)
  File "/home/python/.virtualenvs/django_meiduo/lib/python3.5/site-packages/django/core/handlers/base.py", line 185, in _get_response
    response = wrapped_callback(request, *callback_args, **callback_kwargs)
  File "/home/python/.virtualenvs/django_meiduo/lib/python3.5/site-packages/django/views/decorators/csrf.py", line 58, in wrapped_view
    return view_func(*args, **kwargs)
  File "/home/python/.virtualenvs/django_meiduo/lib/python3.5/site-packages/django/views/generic/base.py", line 68, in view
    return self.dispatch(request, *args, **kwargs)
  File "/home/python/.virtualenvs/django_meiduo/lib/python3.5/site-packages/rest_framework/views.py", line 485, in dispatch
    self.response = self.finalize_response(request, response, *args, **kwargs)
  File "/home/python/.virtualenvs/django_meiduo/lib/python3.5/site-packages/rest_framework/views.py", line 400, in finalize_response
    % type(response)
AssertionError: Expected a `Response`, `HttpResponse` or `HttpStreamingResponse` to be returned from the view, but received a `<class 'NoneType'>`
ERROR 2019-02-20 16:04:24,934 basehttp 124 "GET /verifications/smscodes/13111111111/?text=7ijl&image_code_id=2b196af9-c6bf-4823-94fa-872bdae408ff HTTP/1.1" 500 88812
INFO 2019-02-20 16:07:48,558 basehttp 124 "GET /verifications/imagecodes/52cfa8f8-bfc5-4057-9c4c-49563c338b32/ HTTP/1.1" 200 3383
ERROR 2019-02-20 16:08:27,687 exception 135 Internal Server Error: /verifications/smscodes/13111111111/
Traceback (most recent call last):
  File "/home/python/.virtualenvs/django_meiduo/lib/python3.5/site-packages/django/core/handlers/exception.py", line 41, in inner
    response = get_response(request)
  File "/home/python/.virtualenvs/django_meiduo/lib/python3.5/site-packages/django/core/handlers/base.py", line 187, in _get_response
    response = self.process_exception_by_middleware(e, request)
  File "/home/python/.virtualenvs/django_meiduo/lib/python3.5/site-packages/django/core/handlers/base.py", line 185, in _get_response
    response = wrapped_callback(request, *callback_args, **callback_kwargs)
  File "/home/python/.virtualenvs/django_meiduo/lib/python3.5/site-packages/django/views/decorators/csrf.py", line 58, in wrapped_view
    return view_func(*args, **kwargs)
  File "/home/python/.virtualenvs/django_meiduo/lib/python3.5/site-packages/django/views/generic/base.py", line 68, in view
    return self.dispatch(request, *args, **kwargs)
  File "/home/python/.virtualenvs/django_meiduo/lib/python3.5/site-packages/rest_framework/views.py", line 485, in dispatch
    self.response = self.finalize_response(request, response, *args, **kwargs)
  File "/home/python/.virtualenvs/django_meiduo/lib/python3.5/site-packages/rest_framework/views.py", line 400, in finalize_response
    % type(response)
AssertionError: Expected a `Response`, `HttpResponse` or `HttpStreamingResponse` to be returned from the view, but received a `<class 'NoneType'>`
ERROR 2019-02-20 16:08:27,982 basehttp 124 "GET /verifications/smscodes/13111111111/?text=aewx&image_code_id=52cfa8f8-bfc5-4057-9c4c-49563c338b32 HTTP/1.1" 500 88812
INFO 2019-02-20 16:44:36,346 basehttp 124 "GET /verifications/imagecodes/ffaa49b9-5f14-4727-9d8c-9d13e580685b/ HTTP/1.1" 200 2852
INFO 2019-02-20 16:45:25,377 basehttp 124 "GET /verifications/smscodes/13111111111/?text=opeb&image_code_id=ffaa49b9-5f14-4727-9d8c-9d13e580685b HTTP/1.1" 200 12
INFO 2019-02-20 16:46:03,514 basehttp 124 "GET /verifications/smscodes/13111111111/?text=opeb&image_code_id=ffaa49b9-5f14-4727-9d8c-9d13e580685b HTTP/1.1" 200 12
INFO 2019-02-20 16:47:04,868 basehttp 124 "GET /verifications/imagecodes/9ba162cc-0383-4c27-ae37-be77445d7647/ HTTP/1.1" 200 3140
INFO 2019-02-20 16:48:42,694 basehttp 124 "GET /verifications/smscodes/13111111111/?text=ddyv&image_code_id=9ba162cc-0383-4c27-ae37-be77445d7647 HTTP/1.1" 200 12
INFO 2019-02-20 16:57:08,252 basehttp 124 "GET /verifications/imagecodes/145ee2d1-5d11-4bc6-b537-bbd107770042/ HTTP/1.1" 200 2786
ERROR 2019-02-20 16:57:50,308 exception 135 Internal Server Error: /verifications/smscodes/13111111111/
Traceback (most recent call last):
  File "/home/python/.virtualenvs/django_meiduo/lib/python3.5/site-packages/django/core/handlers/exception.py", line 41, in inner
    response = get_response(request)
  File "/home/python/.virtualenvs/django_meiduo/lib/python3.5/site-packages/django/core/handlers/base.py", line 187, in _get_response
    response = self.process_exception_by_middleware(e, request)
  File "/home/python/.virtualenvs/django_meiduo/lib/python3.5/site-packages/django/core/handlers/base.py", line 185, in _get_response
    response = wrapped_callback(request, *callback_args, **callback_kwargs)
  File "/home/python/.virtualenvs/django_meiduo/lib/python3.5/site-packages/django/views/decorators/csrf.py", line 58, in wrapped_view
    return view_func(*args, **kwargs)
  File "/home/python/.virtualenvs/django_meiduo/lib/python3.5/site-packages/django/views/generic/base.py", line 68, in view
    return self.dispatch(request, *args, **kwargs)
  File "/home/python/.virtualenvs/django_meiduo/lib/python3.5/site-packages/rest_framework/views.py", line 485, in dispatch
    self.response = self.finalize_response(request, response, *args, **kwargs)
  File "/home/python/.virtualenvs/django_meiduo/lib/python3.5/site-packages/rest_framework/views.py", line 400, in finalize_response
    % type(response)
AssertionError: Expected a `Response`, `HttpResponse` or `HttpStreamingResponse` to be returned from the view, but received a `<class 'NoneType'>`
ERROR 2019-02-20 16:57:50,474 basehttp 124 "GET /verifications/smscodes/13111111111/?text=st5y&image_code_id=145ee2d1-5d11-4bc6-b537-bbd107770042 HTTP/1.1" 500 88812
ERROR 2019-02-20 16:58:21,414 exception 135 Internal Server Error: /verifications/smscodes/13111111111/
Traceback (most recent call last):
  File "/home/python/.virtualenvs/django_meiduo/lib/python3.5/site-packages/django/core/handlers/exception.py", line 41, in inner
    response = get_response(request)
  File "/home/python/.virtualenvs/django_meiduo/lib/python3.5/site-packages/django/core/handlers/base.py", line 187, in _get_response
    response = self.process_exception_by_middleware(e, request)
  File "/home/python/.virtualenvs/django_meiduo/lib/python3.5/site-packages/django/core/handlers/base.py", line 185, in _get_response
    response = wrapped_callback(request, *callback_args, **callback_kwargs)
  File "/home/python/.virtualenvs/django_meiduo/lib/python3.5/site-packages/django/views/decorators/csrf.py", line 58, in wrapped_view
    return view_func(*args, **kwargs)
  File "/home/python/.virtualenvs/django_meiduo/lib/python3.5/site-packages/django/views/generic/base.py", line 68, in view
    return self.dispatch(request, *args, **kwargs)
  File "/home/python/.virtualenvs/django_meiduo/lib/python3.5/site-packages/rest_framework/views.py", line 485, in dispatch
    self.response = self.finalize_response(request, response, *args, **kwargs)
  File "/home/python/.virtualenvs/django_meiduo/lib/python3.5/site-packages/rest_framework/views.py", line 400, in finalize_response
    % type(response)
AssertionError: Expected a `Response`, `HttpResponse` or `HttpStreamingResponse` to be returned from the view, but received a `<class 'NoneType'>`
ERROR 2019-02-20 16:58:21,624 basehttp 124 "GET /verifications/smscodes/13111111111/?text=st5y&image_code_id=145ee2d1-5d11-4bc6-b537-bbd107770042 HTTP/1.1" 500 88812
INFO 2019-02-20 17:08:21,156 basehttp 124 "GET /verifications/imagecodes/7a23a1da-dab5-40ba-a861-299da595845c/ HTTP/1.1" 200 3453
INFO 2019-02-20 17:11:56,697 basehttp 124 "GET /verifications/imagecodes/d50a9bc5-6fe0-40d5-811c-1b6bdb5e63f9/ HTTP/1.1" 200 3330
INFO 2019-02-20 17:15:34,307 basehttp 124 "GET /verifications/imagecodes/20f9e10a-38f5-4b83-b1e9-de27a5fee6b6/ HTTP/1.1" 200 3283
ERROR 2019-02-20 17:16:12,985 exception 135 Internal Server Error: /verifications/smscodes/13111111111/
Traceback (most recent call last):
  File "/home/python/.virtualenvs/django_meiduo/lib/python3.5/site-packages/django/core/handlers/exception.py", line 41, in inner
    response = get_response(request)
  File "/home/python/.virtualenvs/django_meiduo/lib/python3.5/site-packages/django/core/handlers/base.py", line 187, in _get_response
    response = self.process_exception_by_middleware(e, request)
  File "/home/python/.virtualenvs/django_meiduo/lib/python3.5/site-packages/django/core/handlers/base.py", line 185, in _get_response
    response = wrapped_callback(request, *callback_args, **callback_kwargs)
  File "/home/python/.virtualenvs/django_meiduo/lib/python3.5/site-packages/django/views/decorators/csrf.py", line 58, in wrapped_view
    return view_func(*args, **kwargs)
  File "/home/python/.virtualenvs/django_meiduo/lib/python3.5/site-packages/django/views/generic/base.py", line 68, in view
    return self.dispatch(request, *args, **kwargs)
  File "/home/python/.virtualenvs/django_meiduo/lib/python3.5/site-packages/rest_framework/views.py", line 485, in dispatch
    self.response = self.finalize_response(request, response, *args, **kwargs)
  File "/home/python/.virtualenvs/django_meiduo/lib/python3.5/site-packages/rest_framework/views.py", line 400, in finalize_response
    % type(response)
AssertionError: Expected a `Response`, `HttpResponse` or `HttpStreamingResponse` to be returned from the view, but received a `<class 'NoneType'>`
ERROR 2019-02-20 17:16:13,165 basehttp 124 "GET /verifications/smscodes/13111111111/?text=shah&image_code_id=d50a9bc5-6fe0-40d5-811c-1b6bdb5e63f9 HTTP/1.1" 500 88812
INFO 2019-02-20 17:38:02,232 basehttp 124 "GET /verifications/imagecodes/ce0e4f45-d7a8-4e54-b52d-b0e78919e146/ HTTP/1.1" 200 2902
INFO 2019-02-20 17:38:28,278 basehttp 124 "GET /verifications/imagecodes/0cc963ae-ade1-470e-8852-d7430845b770/ HTTP/1.1" 200 2680
INFO 2019-02-20 17:40:52,191 basehttp 124 "GET /verifications/imagecodes/f441be05-4353-40f4-ab43-4729b5b054d6/ HTTP/1.1" 200 3296
INFO 2019-02-20 17:43:39,269 basehttp 124 "GET /verifications/imagecodes/858c41db-c855-4a79-aae6-bfa59513b397/ HTTP/1.1" 200 3212
INFO 2019-02-20 17:44:03,887 basehttp 124 "GET /verifications/imagecodes/3572848f-cbe4-425e-8009-192d885a8c74/ HTTP/1.1" 200 2974
INFO 2019-02-20 17:44:12,021 basehttp 124 "GET /verifications/imagecodes/ebd5f79f-16d0-4d85-8c50-8aa47da441d6/ HTTP/1.1" 200 3457
INFO 2019-02-20 17:44:15,448 basehttp 124 "GET /verifications/imagecodes/641bd915-99b1-4094-b067-aae90723e822/ HTTP/1.1" 200 3319
INFO 2019-02-20 17:44:21,117 basehttp 124 "GET /verifications/smscodes/13111111111/?text=xyjq&image_code_id=641bd915-99b1-4094-b067-aae90723e822 HTTP/1.1" 200 12
